<?xml version="1.0" encoding="UTF-8"?>
<testng-results ignored="0" total="4" passed="2" failed="2" skipped="0">
  <reporter-output>
  </reporter-output>
  <suite started-at="2025-04-07T19:33:31 IST" name="Suite" finished-at="2025-04-07T19:33:42 IST" duration-ms="10272">
    <groups>
      <group name="regression">
        <method signature="UserValidations.validateGetUser()[pri:2, instance:org.uma.api.validations.UserValidations@d176a31]" name="validateGetUser" class="org.uma.api.validations.UserValidations"/>
        <method signature="UserValidations.validateUpdateUser()[pri:3, instance:org.uma.api.validations.UserValidations@d176a31]" name="validateUpdateUser" class="org.uma.api.validations.UserValidations"/>
        <method signature="UserValidations.validateDeleteUser()[pri:4, instance:org.uma.api.validations.UserValidations@d176a31]" name="validateDeleteUser" class="org.uma.api.validations.UserValidations"/>
      </group> <!-- regression -->
      <group name="sanity">
        <method signature="UserValidations.validatePostUser()[pri:1, instance:org.uma.api.validations.UserValidations@d176a31]" name="validatePostUser" class="org.uma.api.validations.UserValidations"/>
      </group> <!-- sanity -->
      <group name="UserAPI">
        <method signature="UserValidations.validatePostUser()[pri:1, instance:org.uma.api.validations.UserValidations@d176a31]" name="validatePostUser" class="org.uma.api.validations.UserValidations"/>
        <method signature="UserValidations.validateGetUser()[pri:2, instance:org.uma.api.validations.UserValidations@d176a31]" name="validateGetUser" class="org.uma.api.validations.UserValidations"/>
        <method signature="UserValidations.validateUpdateUser()[pri:3, instance:org.uma.api.validations.UserValidations@d176a31]" name="validateUpdateUser" class="org.uma.api.validations.UserValidations"/>
        <method signature="UserValidations.validateDeleteUser()[pri:4, instance:org.uma.api.validations.UserValidations@d176a31]" name="validateDeleteUser" class="org.uma.api.validations.UserValidations"/>
      </group> <!-- UserAPI -->
    </groups>
    <test started-at="2025-04-07T19:33:31 IST" name="Test1" finished-at="2025-04-07T19:33:42 IST" duration-ms="10272">
      <class name="org.uma.api.validations.UserValidations">
        <test-method is-config="true" signature="setupTestData()[pri:0, instance:org.uma.api.validations.UserValidations@d176a31]" started-at="2025-04-07T19:33:32 IST" name="setupTestData" finished-at="2025-04-07T19:33:32 IST" duration-ms="267" status="PASS">
          <reporter-output>
          </reporter-output>
        </test-method> <!-- setupTestData -->
        <test-method signature="validatePostUser()[pri:1, instance:org.uma.api.validations.UserValidations@d176a31]" started-at="2025-04-07T19:33:32 IST" name="validatePostUser" description="Validate creating a new user" finished-at="2025-04-07T19:33:36 IST" duration-ms="3590" status="PASS">
          <reporter-output>
          </reporter-output>
        </test-method> <!-- validatePostUser -->
        <test-method signature="validateGetUser()[pri:2, instance:org.uma.api.validations.UserValidations@d176a31]" started-at="2025-04-07T19:33:36 IST" name="validateGetUser" description="Validate retrieving a user" finished-at="2025-04-07T19:33:37 IST" duration-ms="1582" status="FAIL">
          <exception class="java.lang.AssertionError">
            <message>
              <![CDATA[expected [200] but found [404]]]>
            </message>
            <full-stacktrace>
              <![CDATA[java.lang.AssertionError: expected [200] but found [404]
at org.testng.Assert.fail(Assert.java:111)
at org.testng.Assert.failNotEquals(Assert.java:1590)
at org.testng.Assert.assertEqualsImpl(Assert.java:150)
at org.testng.Assert.assertEquals(Assert.java:132)
at org.testng.Assert.assertEquals(Assert.java:1431)
at org.testng.Assert.assertEquals(Assert.java:1395)
at org.testng.Assert.assertEquals(Assert.java:1441)
at org.uma.api.validations.UserValidations.validateGetUser(UserValidations.java:52)
at java.base/jdk.internal.reflect.DirectMethodHandleAccessor.invoke(DirectMethodHandleAccessor.java:103)
at java.base/java.lang.reflect.Method.invoke(Method.java:580)
at org.testng.internal.invokers.MethodInvocationHelper.invokeMethod(MethodInvocationHelper.java:141)
at org.testng.internal.invokers.TestInvoker.invokeMethod(TestInvoker.java:687)
at org.testng.internal.invokers.TestInvoker.invokeTestMethod(TestInvoker.java:230)
at org.testng.internal.invokers.MethodRunner.runInSequence(MethodRunner.java:63)
at org.testng.internal.invokers.TestInvoker$MethodInvocationAgent.invoke(TestInvoker.java:995)
at org.testng.internal.invokers.TestInvoker.invokeTestMethods(TestInvoker.java:203)
at org.testng.internal.invokers.TestMethodWorker.invokeTestMethods(TestMethodWorker.java:154)
at org.testng.internal.invokers.TestMethodWorker.run(TestMethodWorker.java:134)
at java.base/java.util.ArrayList.forEach(ArrayList.java:1596)
at org.testng.TestRunner.privateRun(TestRunner.java:741)
at org.testng.TestRunner.run(TestRunner.java:616)
at org.testng.SuiteRunner.runTest(SuiteRunner.java:421)
at org.testng.SuiteRunner.runSequentially(SuiteRunner.java:413)
at org.testng.SuiteRunner.privateRun(SuiteRunner.java:373)
at org.testng.SuiteRunner.run(SuiteRunner.java:312)
at org.testng.SuiteRunnerWorker.runSuite(SuiteRunnerWorker.java:52)
at org.testng.SuiteRunnerWorker.run(SuiteRunnerWorker.java:95)
at org.testng.TestNG.runSuitesSequentially(TestNG.java:1274)
at org.testng.TestNG.runSuitesLocally(TestNG.java:1208)
at org.testng.TestNG.runSuites(TestNG.java:1112)
at org.testng.TestNG.run(TestNG.java:1079)
at org.testng.remote.AbstractRemoteTestNG.run(AbstractRemoteTestNG.java:115)
at org.testng.remote.RemoteTestNG.initAndRun(RemoteTestNG.java:293)
at org.testng.remote.RemoteTestNG.main(RemoteTestNG.java:91)
]]>
            </full-stacktrace>
          </exception> <!-- java.lang.AssertionError -->
          <reporter-output>
          </reporter-output>
        </test-method> <!-- validateGetUser -->
        <test-method signature="validateUpdateUser()[pri:3, instance:org.uma.api.validations.UserValidations@d176a31]" started-at="2025-04-07T19:33:37 IST" name="validateUpdateUser" description="Validate updating a user" finished-at="2025-04-07T19:33:40 IST" duration-ms="2918" status="FAIL">
          <exception class="java.lang.AssertionError">
            <message>
              <![CDATA[expected [Doug] but found [Alison]]]>
            </message>
            <full-stacktrace>
              <![CDATA[java.lang.AssertionError: expected [Doug] but found [Alison]
at org.testng.Assert.fail(Assert.java:111)
at org.testng.Assert.failNotEquals(Assert.java:1590)
at org.testng.Assert.assertEqualsImpl(Assert.java:150)
at org.testng.Assert.assertEquals(Assert.java:132)
at org.testng.Assert.assertEquals(Assert.java:656)
at org.testng.Assert.assertEquals(Assert.java:666)
at org.uma.api.validations.UserValidations.validateUpdateUser(UserValidations.java:73)
at java.base/jdk.internal.reflect.DirectMethodHandleAccessor.invoke(DirectMethodHandleAccessor.java:103)
at java.base/java.lang.reflect.Method.invoke(Method.java:580)
at org.testng.internal.invokers.MethodInvocationHelper.invokeMethod(MethodInvocationHelper.java:141)
at org.testng.internal.invokers.TestInvoker.invokeMethod(TestInvoker.java:687)
at org.testng.internal.invokers.TestInvoker.invokeTestMethod(TestInvoker.java:230)
at org.testng.internal.invokers.MethodRunner.runInSequence(MethodRunner.java:63)
at org.testng.internal.invokers.TestInvoker$MethodInvocationAgent.invoke(TestInvoker.java:995)
at org.testng.internal.invokers.TestInvoker.invokeTestMethods(TestInvoker.java:203)
at org.testng.internal.invokers.TestMethodWorker.invokeTestMethods(TestMethodWorker.java:154)
at org.testng.internal.invokers.TestMethodWorker.run(TestMethodWorker.java:134)
at java.base/java.util.ArrayList.forEach(ArrayList.java:1596)
at org.testng.TestRunner.privateRun(TestRunner.java:741)
at org.testng.TestRunner.run(TestRunner.java:616)
at org.testng.SuiteRunner.runTest(SuiteRunner.java:421)
at org.testng.SuiteRunner.runSequentially(SuiteRunner.java:413)
at org.testng.SuiteRunner.privateRun(SuiteRunner.java:373)
at org.testng.SuiteRunner.run(SuiteRunner.java:312)
at org.testng.SuiteRunnerWorker.runSuite(SuiteRunnerWorker.java:52)
at org.testng.SuiteRunnerWorker.run(SuiteRunnerWorker.java:95)
at org.testng.TestNG.runSuitesSequentially(TestNG.java:1274)
at org.testng.TestNG.runSuitesLocally(TestNG.java:1208)
at org.testng.TestNG.runSuites(TestNG.java:1112)
at org.testng.TestNG.run(TestNG.java:1079)
at org.testng.remote.AbstractRemoteTestNG.run(AbstractRemoteTestNG.java:115)
at org.testng.remote.RemoteTestNG.initAndRun(RemoteTestNG.java:293)
at org.testng.remote.RemoteTestNG.main(RemoteTestNG.java:91)
]]>
            </full-stacktrace>
          </exception> <!-- java.lang.AssertionError -->
          <reporter-output>
          </reporter-output>
        </test-method> <!-- validateUpdateUser -->
        <test-method signature="validateDeleteUser()[pri:4, instance:org.uma.api.validations.UserValidations@d176a31]" started-at="2025-04-07T19:33:40 IST" name="validateDeleteUser" description="Validate deleting a user" finished-at="2025-04-07T19:33:42 IST" duration-ms="1469" status="PASS">
          <reporter-output>
          </reporter-output>
        </test-method> <!-- validateDeleteUser -->
      </class> <!-- org.uma.api.validations.UserValidations -->
    </test> <!-- Test1 -->
  </suite> <!-- Suite -->
</testng-results>
